<?xml version="1.0" ?>
<!-- =================================================================================== -->
<!-- |    This document was autogenerated by xacro from urdf/09-paperarm.urdf.xacro    | -->
<!-- |    EDITING THIS FILE BY HAND IS NOT RECOMMENDED                                 | -->
<!-- =================================================================================== -->
<robot name="paperarm" xmlns:xacro="http://ros.org/wiki/xacro">
  <material name="LightBlue">
    <color rgba="0.5 0.5 1.0 1.0"/>
  </material>
  <material name="LightRed">
    <color rgba="1.0 0.2 0.2 1.0"/>
  </material>
  <material name="LightGreen">
    <color rgba="0.5 1.0 0.5 1.0"/>
  </material>
  <material name="LightGrey">
    <color rgba="0.7 0.7 0.7 1.0"/>
  </material>
  <link name="base_link">
    <visual>
      <geometry>
        <cylinder length="0.1" radius="0.06"/>
      </geometry>
      <origin rpy="0.0 0.0 0.0" xyz="0.0 0.0 0.05"/>
      <material name="LightGrey"/>
    </visual>
  </link>
  <joint name="shoulder_pan_joint" type="revolute">
    <parent link="base_link"/>
    <child link="shoulder_link"/>
    <origin rpy="0.0 0.0 0.0" xyz="0.0 0.0 0.1"/>
    <axis xyz="0 0 1"/>
    <limit effort="150.0" lower="-2.0" upper="2.0" velocity="3.15"/>
  </joint>
  <link name="shoulder_link">
    <visual>
      <geometry>
        <cylinder length="0.1" radius="0.06"/>
      </geometry>
      <origin rpy="0.0 0.0 0.0" xyz="0.0 0.0 0.05"/>
      <material name="LightGrey"/>
    </visual>
  </link>
  <joint name="shoulder_jointX" type="fixed">
    <parent link="shoulder_link"/>
    <child link="shoulder_linkX"/>
    <origin rpy="0.0 0.0 0.0" xyz="0.0 0.0 0.1"/>
  </joint>
  <link name="shoulder_linkX">
    <visual>
      <geometry>
        <cylinder length="0.15" radius="0.05"/>
      </geometry>
      <origin rpy="1.57079632679 0.0 0.0" xyz="0.0 0.0 0.0"/>
      <material name="LightRed"/>
    </visual>
  </link>
  <joint name="shoulder_lift_joint" type="revolute">
    <parent link="shoulder_link"/>
    <child link="upper_arm_link"/>
    <origin rpy="0.0 0.0 0.0" xyz="0.0 0.0 0.1"/>
    <axis xyz="0 1 0"/>
    <limit effort="150.0" lower="-2.0" upper="2.0" velocity="3.15"/>
  </joint>
  <link name="upper_arm_link">
    <visual>
      <geometry>
        <cylinder length="0.3" radius="0.05"/>
      </geometry>
      <origin rpy="0.0 0.0 0.0" xyz="0.0 0.0 0.15"/>
      <material name="LightGrey"/>
    </visual>
  </link>
  <joint name="upper_arm_jointX" type="fixed">
    <parent link="upper_arm_link"/>
    <child link="upper_arm_linkX"/>
    <origin rpy="0.0 0.0 0.0" xyz="0.0 0.0 0.3"/>
  </joint>
  <link name="upper_arm_linkX">
    <visual>
      <geometry>
        <cylinder length="0.15" radius="0.05"/>
      </geometry>
      <origin rpy="1.57079632679 0.0 0.0" xyz="0.0 0.0 0.0"/>
      <material name="LightRed"/>
    </visual>
  </link>
  <joint name="elbow_joint" type="revolute">
    <parent link="upper_arm_link"/>
    <child link="forearm_link"/>
    <origin rpy="0.0 0.0 0.0" xyz="0.0 0.0 0.3"/>
    <axis xyz="0 1 0"/>
    <limit effort="150.0" lower="-2.0" upper="2.0" velocity="3.15"/>
  </joint>
  <link name="forearm_link">
    <visual>
      <geometry>
        <cylinder length="0.2" radius="0.03"/>
      </geometry>
      <origin rpy="0.0 0.0 0.0" xyz="0.0 0.0 0.1"/>
      <material name="LightGrey"/>
    </visual>
  </link>
  <joint name="wrist_1_joint" type="revolute">
    <parent link="forearm_link"/>
    <child link="wrist_1_link"/>
    <origin rpy="0.0 0.0 0.0" xyz="0.0 0.0 0.2"/>
    <axis xyz="0 0 1"/>
    <limit effort="150.0" lower="-2.0" upper="2.0" velocity="3.15"/>
  </joint>
  <link name="wrist_1_link">
    <visual>
      <geometry>
        <cylinder length="0.1" radius="0.03"/>
      </geometry>
      <origin rpy="0.0 0.0 0.0" xyz="0.0 0.0 0.05"/>
      <material name="LightGrey"/>
    </visual>
  </link>
  <joint name="wrist_1_jointX" type="fixed">
    <parent link="wrist_1_link"/>
    <child link="wrist_1_linkX"/>
    <origin rpy="0.0 0.0 0.0" xyz="0.0 0.0 0.1"/>
  </joint>
  <link name="wrist_1_linkX">
    <visual>
      <geometry>
        <cylinder length="0.1" radius="0.0333333333333"/>
      </geometry>
      <origin rpy="1.57079632679 0.0 0.0" xyz="0.0 0.0 0.0"/>
      <material name="LightRed"/>
    </visual>
  </link>
  <joint name="wrist_2_joint" type="revolute">
    <parent link="wrist_1_link"/>
    <child link="wrist_2_link"/>
    <origin rpy="0.0 0.0 0.0" xyz="0.0 0.0 0.1"/>
    <axis xyz="0 1 0"/>
    <limit effort="150.0" lower="-2.0" upper="2.0" velocity="3.15"/>
  </joint>
  <link name="wrist_2_link">
    <visual>
      <geometry>
        <cylinder length="0.05" radius="0.03"/>
      </geometry>
      <origin rpy="0.0 0.0 0.0" xyz="0.0 0.0 0.025"/>
      <material name="LightGrey"/>
    </visual>
  </link>
  <joint name="wrist_3_joint" type="revolute">
    <parent link="wrist_2_link"/>
    <child link="wrist_3_link"/>
    <origin rpy="0.0 0.0 0.0" xyz="0.0 0.0 0.05"/>
    <axis xyz="0 0 1"/>
    <limit effort="150.0" lower="-2.0" upper="2.0" velocity="3.15"/>
  </joint>
  <link name="wrist_3_link">
    <visual>
      <geometry>
        <cylinder length="0.05" radius="0.03"/>
      </geometry>
      <origin rpy="0.0 0.0 0.0" xyz="0.0 0.0 0.025"/>
      <material name="LightGrey"/>
    </visual>
  </link>
  <joint name="ee_fixed_joint" type="fixed">
    <parent link="wrist_3_link"/>
    <child link="ee_link"/>
    <origin rpy="0.0 0.0 0.0" xyz="0.0 0.0 0.05"/>
  </joint>
  <link name="ee_link">
    <collision>
      <geometry>
        <box size="0.01 0.01 0.01"/>
      </geometry>
      <origin rpy="0 0 0" xyz="-0.01 0 0"/>
    </collision>
  </link>
</robot>

